<?xml version="1.0" encoding="utf-8"?>
<robot name="scara2" xmlns:xacro="http://www.ros.org/wiki/xacro">

    <!-- ____________________ base_link ____________________ -->
    <link name="base_link">
      <visual>
        <origin xyz="0 0 0" rpy="1.5707 0 3.1416"/>
        <geometry>
          <mesh scale="0.010 0.010 0.010" filename="package://rms_scara/meshes/scara2/scara2_base_link.stl"/>
        </geometry>
      </visual>
      <collision>
        <origin xyz="0 0 0" rpy="1.5707 0 3.1416"/>
        <geometry>
          <mesh scale="0.010 0.010 0.010" filename="package://rms_scara/meshes/scara2/scara2_base_link.stl"/>
        </geometry>
      </collision>
      <inertial>
        <origin xyz="0.0 0 0"/>
        <mass value="100"/>
        <inertia ixx="0.0" ixy="0.0" ixz="0.0"
                 iyy="0.0" iyz="0.0" 
                 izz="0.03"/>
      </inertial>
    </link>
    <gazebo reference="base_link">
      <material>Gazebo/White</material>
    </gazebo>

    <!-- ____________________ Shafts and screw ____________________ -->

    <joint name="shaft1_joint" type="fixed">
      <origin xyz="0.0175 0.005 0.0303" rpy="0 0 0" />
      <parent link="joint2_link"/>
      <child link="shaft1_link" />
    </joint>

    <link name="shaft1_link">
      <visual>
        <geometry>
         <mesh scale="0.01 0.01 0.01" filename="package://rms_scara/meshes/scara2/scara2_shaft.stl"/>
        </geometry>
        <origin xyz="0 0 0" rpy="0 0 0"/> 
      </visual>
      <collision>
        <geometry>
         <mesh scale="0.01 0.01 0.01" filename="package://rms_scara/meshes/scara2/scara2_shaft.stl"/>
        </geometry>
        <origin xyz="0 0 0" rpy="0 0 0"/>
      </collision>
      <inertial>
        <origin xyz="0.0 0 0"/>
        <mass value="0.5"/>
        <inertia ixx="0.01" ixy="0.0" ixz="0.0"
                 iyy="0.01" iyz="0.0" 
                 izz="0.03"/>
      </inertial>
    </link>

    <joint name="shaft2_joint" type="fixed">
      <origin xyz="-0.035 0.005 0" rpy="0 0 0" />
      <parent link="joint2_link"/>
      <child link="shaft2_link" />
    </joint>

    <link name="shaft2_link">
      <visual>
        <geometry>
         <mesh scale="0.01 0.01 0.01" filename="package://rms_scara/meshes/scara2/scara2_shaft.stl"/>
        </geometry>
        <origin xyz="0 0 0" rpy="0 0 0"/> 
      </visual>
      <collision>
        <geometry>
         <mesh scale="0.01 0.01 0.01" filename="package://rms_scara/meshes/scara2/scara2_shaft.stl"/>
        </geometry>
        <origin xyz="0 0 0" rpy="0 0 0"/>
      </collision>
      <inertial>
        <origin xyz="0.0 0 0"/>
        <mass value="0.5"/>
        <inertia ixx="0.01" ixy="0.0" ixz="0.0"
                 iyy="0.01" iyz="0.0" 
                 izz="0.03"/>
      </inertial>
    </link>

    <joint name="shaft3_joint" type="fixed">
      <origin xyz="0.0175 0.01 -0.0303" rpy="0 0 0" />
      <parent link="joint2_link"/>
      <child link="shaft3_link" />
    </joint>

    <link name="shaft3_link">
      <visual>
        <geometry>
         <mesh scale="0.01 0.01 0.01" filename="package://rms_scara/meshes/scara2/scara2_shaft.stl"/>
        </geometry>
        <origin xyz="0 0 0" rpy="0 0 0"/> 
      </visual>
      <collision>
        <geometry>
         <mesh scale="0.01 0.01 0.01" filename="package://rms_scara/meshes/scara2/scara2_shaft.stl"/>
        </geometry>
        <origin xyz="0 0 0" rpy="0 0 0"/>
      </collision>
      <inertial>
        <origin xyz="0.0 0 0"/>
        <mass value="0.5"/>
        <inertia ixx="0.01" ixy="0.0" ixz="0.0"
                 iyy="0.01" iyz="0.0" 
                 izz="0.03"/>
      </inertial>
    </link>

    <!--
    <joint name="screw_joint" type="fixed">
      <origin xyz="0.045 0 0" rpy="0 0 0" />
      <parent link="joint2_link"/>
      <child link="screw_link" />
    </joint>

    <link name="screw_link">
      <visual>
        <geometry>
         <mesh scale="0.01 0.01 0.01" filename="package://rms_scara/meshes/scara2/scara2_screw.stl"/>
        </geometry>
        <origin xyz="0 0 0" rpy="0 0 0"/> 
      </visual>
      <collision>
        <geometry>
         <mesh scale="0.01 0.01 0.01" filename="package://rms_scara/meshes/scara2/scara2_screw.stl"/>
        </geometry>
        <origin xyz="0 0 0" rpy="0 0 0"/>
      </collision>
      <inertial>
        <origin xyz="0.0 0 0"/>
        <mass value="0.5"/>
        <inertia ixx="0.01" ixy="0.0" ixz="0.0"
                 iyy="0.01" iyz="0.0" 
                 izz="0.03"/>
      </inertial>
    </link>
    -->

    <!-- ____________________ Hat ____________________ -->

    <joint name="top_joint" type="fixed">
      <origin xyz="0 0.41 0" rpy="0 3.141 3.14" />
      <parent link="joint2_link"/>
      <child link="top_link" />
    </joint>

    <link name="top_link">
      <visual>
        <geometry>
         <mesh scale="0.01 0.01 0.01" filename="package://rms_scara/meshes/scara2/scara2_top.stl"/>
        </geometry>
        <origin xyz="0 0 0" rpy="0 0 0"/> 
      </visual>
      <collision>
        <geometry>
         <mesh scale="0.01 0.01 0.01" filename="package://rms_scara/meshes/scara2/scara2_top.stl"/>
        </geometry>
        <origin xyz="0 0 0" rpy="0 0 0"/>
      </collision>
      <inertial>
        <origin xyz="0.0 0 0"/>
        <mass value="0.5"/>
        <inertia ixx="0.01" ixy="0.0" ixz="0.0"
                 iyy="0.01" iyz="0.0" 
                 izz="0.03"/>
      </inertial>
    </link>
    
    <!-- ____________________ Joints ____________________ -->

    <joint name="joint1_joint" type="prismatic">
      <origin xyz="0 0.115 0" rpy="0 0.523 0" />
      <parent link="joint2_link"/>
      <child link="joint1_link" />
      <axis xyz="0 1 0"/>
      <limit effort="1000.0" lower="0.0" upper="0.26" velocity="0.2"/>
    </joint>

    <link name="joint1_link">
      <visual>
        <geometry>
         <mesh scale="0.01 0.01 0.01" filename="package://rms_scara/meshes/scara2/scara2_joint1.stl"/>
        </geometry>
        <origin xyz="0 0 0" rpy="0 0 0"/> 
      </visual>
      <collision>
        <geometry>
         <mesh scale="0.01 0.01 0.01" filename="package://rms_scara/meshes/scara2/scara2_joint1.stl"/>
        </geometry>
        <origin xyz="0 0 0" rpy="0 0 0"/>
      </collision>
      <inertial>
        <origin xyz="0.0 0 0"/>
        <mass value="0.5"/>
        <inertia ixx="0.01" ixy="0.0" ixz="0.0"
                 iyy="0.01" iyz="0.0" 
                 izz="0.03"/>
      </inertial>
    </link>
    
    <transmission name="trans_joint1_link">
      <type>transmission_interface/SimpleTransmission</type>
      <joint name="joint1_joint">
        <hardwareInterface>hardware_interface/EffortJointInterface</hardwareInterface>
      </joint>
      <actuator name="ac_joint1_link">
        <hardwareInterface>hardware_interface/EffortJointInterface</hardwareInterface>
        <mechanicalReduction>1</mechanicalReduction>
      </actuator>
    </transmission>

    <gazebo reference="joint1_link">
      <material>Gazebo/Yellow</material>
    </gazebo>


    <joint name="joint2_joint" type="revolute">
      <origin xyz="0 0 0.035" rpy="1.5707 0 0"/>
      <parent link="base_link"/>
      <child link="joint2_link" />
      <axis xyz="0 1 0"/>
      <limit effort="1000.0" lower="-2.80" upper="2.80" velocity="0.2"/>
    </joint>

    <link name="joint2_link">
      <visual>
        <geometry>
         <mesh scale="0.01 0.01 0.01" filename="package://rms_scara/meshes/scara2/scara2_joint2.stl"/>
        </geometry>
        <origin xyz="0 0 0" rpy="0 0 0"/>
      </visual>
      <collision>
        <geometry>
         <mesh scale="0.01 0.01 0.01" filename="package://rms_scara/meshes/scara2/scara2_joint2.stl"/>
        </geometry>
        <origin xyz="0 0 0" rpy="0 0 0"/>
      </collision>
      <inertial>
        <origin xyz="0.0 0 0"/>
        <mass value="0.5"/>
        <inertia ixx="0.01" ixy="0.0" ixz="0.0"
                 iyy="0.01" iyz="0.0" 
                 izz="0.03"/>
      </inertial>
    </link>

    <transmission name="trans_joint2_link">
      <type>transmission_interface/SimpleTransmission</type>
      <joint name="joint2_joint">
        <hardwareInterface>hardware_interface/EffortJointInterface</hardwareInterface>
      </joint>
      <actuator name="ac_joint2_link">
        <hardwareInterface>hardware_interface/EffortJointInterface</hardwareInterface>
        <mechanicalReduction>1</mechanicalReduction>
      </actuator>
    </transmission>

    <gazebo reference="joint2_link">
      <material>Gazebo/Orange</material>
    </gazebo>

    <joint name="joint3_joint" type="revolute">
      <origin xyz="0 -0.035 -0.15" rpy="3.14 3.14 0" />
      <parent link="joint1_link"/>
      <child link="joint3_link" />
      <axis xyz="0 1 0"/>
      <limit effort="1000.0" lower="-2.8" upper="2.8" velocity="0.1"/>
    </joint>
    <link name="joint3_link">
      <visual>
        <geometry>
         <mesh scale="0.01 0.01 0.01" filename="package://rms_scara/meshes/scara2/scara2_joint3.stl"/>
        </geometry>
        <origin xyz="0 0 0" rpy="0 0 0"/> 
      </visual>
      <collision>
        <geometry>
         <mesh scale="0.01 0.01 0.01" filename="package://rms_scara/meshes/scara2/scara2_joint3.stl"/>
        </geometry>
        <origin xyz="0 0 0" rpy="0 0 0"/> 
      </collision>
      <inertial>
        <origin xyz="0.0 0 0"/>
        <mass value="0.5"/>
        <inertia ixx="0.01" ixy="0.0" ixz="0.0"
                 iyy="0.01" iyz="0.0" 
                 izz="0.03"/>
      </inertial>
    </link>

    <transmission name="trans_joint3_link">
      <type>transmission_interface/SimpleTransmission</type>
      <joint name="joint3_joint">
        <hardwareInterface>hardware_interface/EffortJointInterface</hardwareInterface>
      </joint>
      <actuator name="ac_joint3_link">
        <hardwareInterface>hardware_interface/EffortJointInterface</hardwareInterface>
        <mechanicalReduction>1</mechanicalReduction>
      </actuator>
    </transmission>

    <gazebo reference="joint3_link">
      <material>Gazebo/Red</material>
    </gazebo>

    <!-- ____________________ Gripper ____________________ -->

    
    <joint name="gripper_main_joint" type="fixed">
      <origin xyz="0 0.070 -0.12" rpy="-1.57 3.14 3.14" />
      <parent link="joint3_link"/>
      <child link="gripper_main_link" />
    </joint>
    <link name="gripper_main_link">
      <visual>
        <geometry>
         <mesh scale="0.001 0.001 0.001" filename="package://rms_scara/meshes/scara2/scara2_gripper_main.stl"/>
        </geometry>
        <origin xyz="0 0 0" rpy="0 0 0"/> 
      </visual>
      <collision>
        <geometry>
         <mesh scale="0.001 0.001 0.001" filename="package://rms_scara/meshes/scara2/scara2_gripper_main.stl"/>
        </geometry>
        <origin xyz="0 0 0" rpy="0 0 0"/> 
      </collision>
      <inertial>
        <origin xyz="0.0 0 0"/>
        <mass value="0.5"/>
        <inertia ixx="0.01" ixy="0.0" ixz="0.0"
                 iyy="0.01" iyz="0.0" 
                 izz="0.03"/>
      </inertial>
    </link>

    <gazebo reference="gripper_main_link">
      <material>Gazebo/Red</material>
    </gazebo>
    
    <joint name="gripper_right_joint" type="prismatic">
      <origin xyz="0.0078 -0.01 -0.05" rpy="1.57 0 0" />
      <parent link="gripper_main_link"/>
      <child link="gripper_right_link" />
      <axis xyz="1 0 0"/>
      <limit effort="1000.0" lower="0" upper="0.025" velocity="0.1"/>
    </joint>
    <link name="gripper_right_link">
      <visual>
        <geometry>
         <mesh scale="0.001 0.001 0.001" filename="package://rms_scara/meshes/scara2/scara2_gripper_right_2.stl"/>
        </geometry>
        <origin xyz="0 0 0" rpy="0 0 0"/> 
      </visual>
      <collision>
        <geometry>
         <mesh scale="0.001 0.001 0.001" filename="package://rms_scara/meshes/scara2/scara2_gripper_right_2.stl"/>
        </geometry>
        <origin xyz="0 0 0" rpy="0 0 0"/> 
      </collision>
      <inertial>
        <origin xyz="0.0 0 0"/>
        <mass value="0.5"/>
        <inertia ixx="0.01" ixy="0.0" ixz="0.0"
                 iyy="0.01" iyz="0.0" 
                 izz="0.03"/>
      </inertial>
    </link>

    <transmission name="trans_gripper_right_link">
      <type>transmission_interface/SimpleTransmission</type>
      <joint name="gripper_right_joint">
        <hardwareInterface>hardware_interface/EffortJointInterface</hardwareInterface>
      </joint>
      <actuator name="ac_gripper_right_link">
        <hardwareInterface>hardware_interface/EffortJointInterface</hardwareInterface>
        <mechanicalReduction>1</mechanicalReduction>
      </actuator>
    </transmission>

    <gazebo reference="gripper_right_link">
      <material>Gazebo/Purple</material>
    </gazebo>

    
    <joint name="gripper_left_joint" type="prismatic">
      <origin xyz="-0.0078 -0.05 -0.05" rpy="1.57 0 3.14" />
      <parent link="gripper_main_link"/>
      <child link="gripper_left_link" />
      <axis xyz="1 0 0"/>
      <limit effort="1000.0" lower="0" upper="0.025" velocity="0.1"/>
    </joint>
    <link name="gripper_left_link">
      <visual>
        <geometry>
         <mesh scale="0.001 0.001 0.001" filename="package://rms_scara/meshes/scara2/scara2_gripper_left_2.stl"/>
        </geometry>
        <origin xyz="0 0 0" rpy="0 0 0"/> 
      </visual>
      <collision>
        <geometry>
         <mesh scale="0.001 0.001 0.001" filename="package://rms_scara/meshes/scara2/scara2_gripper_left_2.stl"/>
        </geometry>
        <origin xyz="0 0 0" rpy="0 0 0"/> 
      </collision>
      <inertial>
        <origin xyz="0.0 0 0"/>
        <mass value="0.5"/>
        <inertia ixx="0.01" ixy="0.0" ixz="0.0"
                 iyy="0.01" iyz="0.0" 
                 izz="0.03"/>
      </inertial>
    </link>

    <transmission name="trans_gripper_left_link">
      <type>transmission_interface/SimpleTransmission</type>
      <joint name="gripper_left_joint">
        <hardwareInterface>hardware_interface/EffortJointInterface</hardwareInterface>
      </joint>
      <actuator name="ac_gripper_left_link">
        <hardwareInterface>hardware_interface/EffortJointInterface</hardwareInterface>
        <mechanicalReduction>1</mechanicalReduction>
      </actuator>
    </transmission>

    <gazebo reference="gripper_left_link">
      <material>Gazebo/Purple</material>
    </gazebo>

    <!-- ____________________ Camera ____________________ -->

    <joint name="cam_joint" type="fixed">
      <origin xyz="0 -0.12 0.15" rpy="0 2.0 -1.57"/>
      <parent link="gripper_main_link"/>
      <child link="cam_link" />
    </joint> 

    <link name="cam_link">
      <!-- 
      <visual>
        <geometry>
          <cylinder length="0.01" radius="0.01"/>
        </geometry>
        <origin xyz="0 0 0" rpy="0 0 0"/>
      </visual>
      <collision>
        <geometry>
          <cylinder length="0.1" radius="0.1"/>
        </geometry>
        <origin xyz="0 0 0" rpy="0 0 0"/>
      </collision>
      <inertial>
        <origin xyz="0.0 0 0"/>
        <mass value="0.5"/>
        <inertia ixx="0.01" ixy="0.0" ixz="0.0"
                 iyy="0.01" iyz="0.0" 
                 izz="0.03"/>
      </inertial>
      -->
    </link>

    <!-- ____________________ Plugins ____________________ -->
    <gazebo>
      <plugin name="gazebo_ros_control" filename="libgazebo_ros_control.so">
      </plugin>
      <robotNamespace>/rms</robotNamespace>
      <robotParam>/rms/robot_description</robotParam>
    </gazebo>

    <!-- Camera -->
    <gazebo reference="cam_link"><sensor type="camera" name="myCam">
      <update_rate>30.0</update_rate>
      <camera name="head">
        <horizontal_fov>1.04</horizontal_fov>
        <image>
          <width>720</width>
          <height>480</height>
          <format>R8G8B8</format>
        </image>
        <clip>
          <near>0.1</near>
          <far>50</far>
        </clip>
      </camera>
      <plugin name="camera_controller" filename="libgazebo_ros_camera.so">
        <alwaysOn>true</alwaysOn>
        <updateRate>0</updateRate>
        <cameraName>camera1</cameraName>
        <imageTopicName>image_raw</imageTopicName>
        <cameraInfoTopicName>camera_info</cameraInfoTopicName>
        <frameName>camera</frameName>
        <hackBaseline>0.07</hackBaseline>
        <distortionK1>0.0</distortionK1>
        <distortionK2>0.0</distortionK2>
        <distortionK3>0.0</distortionK3>
        <distortionT1>0.0</distortionT1>
        <distortionT2>0.0</distortionT2>
      </plugin>
      </sensor>
    </gazebo>

</robot>
